Workbook

Sheet Cálculo
A1: PREVISIÓN DE CARGAS PARA SUMINISTROS EN BAJA TENSIÓN – ITC-BT 10
A2: Celdas amarillas con texto azul = datos a introducir. El resto son fórmulas. Datos cargados actualmente: ejemplo del PDF.
A4: 1. VIVIENDAS (P1)
A5: Grado de electrificación | B5: Potencia a 230 V (W) | C5: Calibre IGA (A) | D5: Nº de viviendas
A6: Básica | B6: 5750 | C6: 25 | D6: 8
A7: Básica | B7: 7360 | C7: 32 | D7: 0
A8: Elevada | B8: 9200 | C8: 40 | D8: 3
A9: Elevada | B9: 11500 | C9: 50 | D9: 0
A10: Elevada | B10: 14490 | C10: 63 | D10: 0
A11: Total de viviendas (n) | D11: =SUM(D6:D10) -> 11
A12: Potencia media por vivienda Pmedia (W) | D12: =IF(D11=0,0,SUMPRODUCT(B6:B10,D6:D10)/D11) -> 6690.9091
A13: Coeficiente de simultaneidad Cs | D13: =IF(D11=0,0,IF(D11<=21,INDEX(Tablas!B29:B49,D11),Tablas!B49+(D11-21)*Tablas!B25)) -> 9.2
A14: P1 – Potencia viviendas = Pmedia × Cs (W) | D14: =D12*D13 -> 61556.364
A17: 2. SERVICIOS GENERALES (P2)
A18: Ascensores (× coef. 1,3) | B18: Tipo ITA (opcional) | C18: Potencia unitaria | D18: Unidad | E18: P (W) | F18: P × coef. (W)
A19: Ascensor 1 | C19: 5 | D19: CV | E19: =IF(B19<>"",INDEX(Tablas!$H$29:$H$34,MATCH(B19,Tablas!$D$29:$D$34,0))*1000,C19*IF(D19="CV",Tablas!$B$6,IF(D19="kW",1000,1))) -> 3680 | F19: =E19*Tablas!$B$7 -> 4784
A20: Ascensor 2 | D20: CV | E20: =IF(B20<>"",INDEX(Tablas!$H$29:$H$34,MATCH(B20,Tablas!$D$29:$D$34,0))*1000,C20*IF(D20="CV",Tablas!$B$6,IF(D20="kW",1000,1))) -> 0 | F20: =E20*Tablas!$B$7 -> 0
A21: Ascensor 3 | D21: CV | E21: =IF(B21<>"",INDEX(Tablas!$H$29:$H$34,MATCH(B21,Tablas!$D$29:$D$34,0))*1000,C21*IF(D21="CV",Tablas!$B$6,IF(D21="kW",1000,1))) -> 0 | F21: =E21*Tablas!$B$7 -> 0
A22: Subtotal ascensores (W) | F22: =SUM(F19:F21) -> 4784
A24: Motores y otras cargas (el motor mayor × 1,25) | B24: ¿Es motor? | C24: Potencia unitaria | D24: Unidad | E24: P (W) | F24: P motor (W)
A25: Grupo de presión | B25: Sí | C25: 1 | D25: CV | E25: =C25*IF(D25="CV",Tablas!$B$6,IF(D25="kW",1000,1)) -> 736 | F25: =IF(B25="Sí",E25,0) -> 736
A26: Depuradora | B26: Sí | D26: CV | E26: =C26*IF(D26="CV",Tablas!$B$6,IF(D26="kW",1000,1)) -> 0 | F26: =IF(B26="Sí",E26,0) -> 0
A27: Otros motores | B27: Sí | D27: CV | E27: =C27*IF(D27="CV",Tablas!$B$6,IF(D27="kW",1000,1)) -> 0 | F27: =IF(B27="Sí",E27,0) -> 0
A28: Otras cargas (no motor) | B28: No | D28: W | E28: =C28*IF(D28="CV",Tablas!$B$6,IF(D28="kW",1000,1)) -> 0 | F28: =IF(B28="Sí",E28,0) -> 0
A29: Suma de potencias (W) | E29: =SUM(E25:E28) -> 736
A30: Incremento del motor de mayor potencia (W) | E30: =(Tablas!B8-1)*MAX(F25:F28) -> 184
A31: Subtotal motores y otras cargas (W) | E31: =E29+E30 -> 920
A33: Alumbrado (lámparas de descarga × 1,8) | B33: Superficie (m²) | C33: Tipo de lámpara | D33: Potencia directa (W) | E33: P base (W) | F33: P × coef. (W)
A34: Portal y espacios comunes | C34: Fluorescencia/descarga | E34: =IF(D34>0,D34,B34*IF(C34="Incandescencia",Tablas!$B$21,Tablas!$B$22)) -> 0 | F34: =E34*IF(C34="Incandescencia",1,Tablas!$B$9) -> 0
A35: Caja de escalera | C35: Fluorescencia/descarga | E35: =IF(D35>0,D35,B35*IF(C35="Incandescencia",Tablas!$B$23,Tablas!$B$24)) -> 0 | F35: =E35*IF(C35="Incandescencia",1,Tablas!$B$9) -> 0
A36: Alumbrado con potencia instalada conocida | C36: Fluorescencia/descarga | D36: 1500 | E36: =D36 -> 1500 | F36: =E36*IF(C36="Incandescencia",1,Tablas!$B$9) -> 2700
A37: Subtotal alumbrado (W) | F37: =SUM(F34:F36) -> 2700
A39: P2 – Potencia servicios generales (W) | F39: =F22+E31+F37 -> 8404
A42: 3. LOCALES COMERCIALES, OFICINAS E INDUSTRIAS (P3)
A43: Descripción | B43: Tipo | C43: Superficie (m²) | D43: Previsión real (W) (si se conoce) | E43: Previsión por m² (W) | F43: Mínimo por abonado (W) | G43: P prevista (W)
A44: Local 1 | B44: Comercial/oficina | C44: 50 | E44: =C44*IF(B44="Industria",Tablas!$B$12,Tablas!$B$10) -> 5000 | F44: =IF(B44="Industria",Tablas!$B$13,Tablas!$B$11) -> 3450 | G44: =IF(AND(C44=0,D44=0),0,MAX(D44,E44,F44)) -> 5000
A45: Local 2 | B45: Comercial/oficina | C45: 30 | E45: =C45*IF(B45="Industria",Tablas!$B$12,Tablas!$B$10) -> 3000 | F45: =IF(B45="Industria",Tablas!$B$13,Tablas!$B$11) -> 3450 | G45: =IF(AND(C45=0,D45=0),0,MAX(D45,E45,F45)) -> 3450
A46: Local 3 | B46: Comercial/oficina | E46: =C46*IF(B46="Industria",Tablas!$B$12,Tablas!$B$10) -> 0 | F46: =IF(B46="Industria",Tablas!$B$13,Tablas!$B$11) -> 3450 | G46: =IF(AND(C46=0,D46=0),0,MAX(D46,E46,F46)) -> 0
A47: Local 4 | B47: Comercial/oficina | E47: =C47*IF(B47="Industria",Tablas!$B$12,Tablas!$B$10) -> 0 | F47: =IF(B47="Industria",Tablas!$B$13,Tablas!$B$11) -> 3450 | G47: =IF(AND(C47=0,D47=0),0,MAX(D47,E47,F47)) -> 0
A48: Local 5 | B48: Comercial/oficina | E48: =C48*IF(B48="Industria",Tablas!$B$12,Tablas!$B$10) -> 0 | F48: =IF(B48="Industria",Tablas!$B$13,Tablas!$B$11) -> 3450 | G48: =IF(AND(C48=0,D48=0),0,MAX(D48,E48,F48)) -> 0
...

Sheet Resumen
A1: RESUMEN DE PREVISIÓN DE CARGAS Y SECCIÓN DE LÍNEAS
A2: Todo son fórmulas enlazadas a la hoja 'Cálculo'. Intensidad trifásica: I = P / (√3 · U · cos φ).
A3: POTENCIAS DE LA FINCA (sin IRVE)
A4: P1 – Viviendas (W) | B4: =Cálculo!D14 -> 61556.364
A5: P2 – Servicios generales (W) | B5: =Cálculo!F39 -> 8404
A6: P3 – Locales comerciales, oficinas e industrias (W) | B6: =Cálculo!G52 -> 8450
A7: P4 – Garajes (W) | B7: =Cálculo!F60 -> 4800
A8: P FINCA = P1 + P2 + P3 + P4 (W) | B8: =SUM(B4:B7) -> 83210.364
A10: IRVE: COMPARATIVA DE OPCIONES Y SECCIÓN DE LA LÍNEA (cobre XLPE, ver Tablas)
A11: Opción | B11: P IRVE (W) | C11: P TOTAL (W) | D11: I total (A) | E11: Sección línea total (mm²) | F11: I finca (A) | G11: Sección finca (mm²) | H11: I IRVE (A) | I11: Sección IRVE (mm²)
A12: 1 – Sin SPL | B12: =Cálculo!D67 -> 110400 | C12: =$B$8+B12 -> 193610.36 | D12: =C12/(SQRT(3)*Tablas!$B$4*Tablas!$B$5) -> 279.45249 | E12: =IF(D12=0,"-",IF(D12>MAX(Tablas!$B$55:$B$69),"> 240",INDEX(Tablas!$A$55:$A$69,COUNTIF(Tablas!$B$55:$B$69,"<"&D12)+1))) -> 150 | F12: =$B$8/(SQRT(3)*Tablas!$B$4*Tablas!$B$5) -> 120.10381 | G12: =IF(F12=0,"-",IF(F12>MAX(Tablas!$B$55:$B$69),"> 240",INDEX(Tablas!$A$55:$A$69,COUNTIF(Tablas!$B$55:$B$69,"<"&F12)+1))) -> 35 | H12: =B12/(SQRT(3)*Tablas!$B$4*Tablas!$B$5) -> 159.34867 | I12: =IF(H12=0,"-",IF(H12>MAX(Tablas!$B$55:$B$69),"> 240",INDEX(Tablas!$A$55:$A$69,COUNTIF(Tablas!$B$55:$B$69,"<"&H12)+1))) -> 70
A13: 2 – Con SPL | B13: =Cálculo!D68 -> 33120 | C13: =$B$8+B13 -> 116330.36 | D13: =C13/(SQRT(3)*Tablas!$B$4*Tablas!$B$5) -> 167.90842 | E13: =IF(D13=0,"-",IF(D13>MAX(Tablas!$B$55:$B$69),"> 240",INDEX(Tablas!$A$55:$A$69,COUNTIF(Tablas!$B$55:$B$69,"<"&D13)+1))) -> 70 | F13: =$B$8/(SQRT(3)*Tablas!$B$4*Tablas!$B$5) -> 120.10381 | G13: =IF(F13=0,"-",IF(F13>MAX(Tablas!$B$55:$B$69),"> 240",INDEX(Tablas!$A$55:$A$69,COUNTIF(Tablas!$B$55:$B$69,"<"&F13)+1))) -> 35 | H13: =B13/(SQRT(3)*Tablas!$B$4*Tablas!$B$5) -> 47.804602 | I13: =IF(H13=0,"-",IF(H13>MAX(Tablas!$B$55:$B$69),"> 240",INDEX(Tablas!$A$55:$A$69,COUNTIF(Tablas!$B$55:$B$69,"<"&H13)+1))) -> 10
A14: 3 – Mínimo de plazas (10 %) | B14: =Cálculo!D69 -> 11040 | C14: =$B$8+B14 -> 94250.364 | D14: =C14/(SQRT(3)*Tablas!$B$4*Tablas!$B$5) -> 136.03868 | E14: =IF(D14=0,"-",IF(D14>MAX(Tablas!$B$55:$B$69),"> 240",INDEX(Tablas!$A$55:$A$69,COUNTIF(Tablas!$B$55:$B$69,"<"&D14)+1))) -> 50 | F14: =$B$8/(SQRT(3)*Tablas!$B$4*Tablas!$B$5) -> 120.10381 | G14: =IF(F14=0,"-",IF(F14>MAX(Tablas!$B$55:$B$69),"> 240",INDEX(Tablas!$A$55:$A$69,COUNTIF(Tablas!$B$55:$B$69,"<"&F14)+1))) -> 35 | H14: =B14/(SQRT(3)*Tablas!$B$4*Tablas!$B$5) -> 15.934867 | I14: =IF(H14=0,"-",IF(H14>MAX(Tablas!$B$55:$B$69),"> 240",INDEX(Tablas!$A$55:$A$69,COUNTIF(Tablas!$B$55:$B$69,"<"&H14)+1))) -> 1.5
A16: Nota: en el PDF la opción 1 se resuelve con dos líneas separadas (IRVE y finca: columnas F–I); en las opciones 2 y 3 se usa una única línea con la corriente total (columnas D–E).

Sheet Tablas
A1: TABLAS Y PARÁMETROS (REBT ITC-BT 10)
A2: Valores en azul = editables si cambia la normativa. Fuente: PDF 'ITC-BT 10 Previsión de cargas' (PLC Madrid) y REBT.
A3: PARÁMETROS
A4: Tensión de línea trifásica (V) | B4: 400
A5: Factor de potencia cos φ | B5: 1
A6: Equivalencia 1 CV (W) | B6: 736
A7: Coeficiente ascensores | B7: 1.3
A8: Coeficiente motor de mayor potencia | B8: 1.25
A9: Coeficiente lámparas de descarga (fluorescentes…) | B9: 1.8
A10: Comercial/oficina: densidad (W/m²) | B10: 100
A11: Comercial/oficina: mínimo por abonado (W a 230 V) | B11: 3450
A12: Industria: densidad (W/m²) | B12: 125
A13: Industria: mínimo por abonado (W a 230 V) | B13: 10350
A14: Garaje ventilación natural (W/m²) | B14: 10
A15: Garaje ventilación forzada (W/m²) | B15: 20
... A25: Viviendas n>21: incremento de Cs por vivienda | B25: 0.5
A27: COEFICIENTE DE SIMULTANEIDAD – VIVIENDAS | D27: ASCENSORES (ITC-BT 10, tabla ITA)
A28: Nº viviendas (n) | B28: Coeficiente de simultaneidad | D28: Tipo de aparato elevador | E28: Carga (kg) | F28: Nº personas | G28: Velocidad (m/s) | H28: Potencia (kW)
A29: 1 | B29: 1 | D29: ITA-1 | E29: 400 | F29: 5 | G29: 0.63 | H29: 4.5
A30: 2 | B30: 2 | D30: ITA-2 | E30: 400 | F30: 5 | G30: 1 | H30: 7.5
A31: 3 | B31: 3 | D31: ITA-3 | E31: 630 | F31: 8 | G31: 1 | H31: 11.5
A32: 4 | B32: 3.8 | D32: ITA-4 | E32: 630 | F32: 8 | G32: 1.6 | H32: 18.5
A33: 5 | B33: 4.6 | D33: ITA-5 | E33: 1000 | F33: 13 | G33: 1.6 | H33: 29.5
A34: 6 | B34: 5.4 | D34: ITA-6 | E34: 1000 | F34: 13 | G34: 2.5 | H34: 46
A35: 7 | B35: 6.2
A36: 8 | B36: 7
A37: 9 | B37: 7.8
A38: 10 | B38: 8.5
A39: 11 | B39: 9.2
A40: 12 | B40: 9.9
A41: 13 | B41: 10.6
A42: 14 | B42: 11.3
A43: 15 | B43: 11.9
A44: 16 | B44: 12.5
A45: 17 | B45: 13.1
A46: 18 | B46: 13.7
... A49: 21 | B49: 15.3
A50: n > 21: Cs = 15,3 + (n − 21) × incremento (B25)
A53: INTENSIDAD ADMISIBLE – COBRE, 3 conductores cargados, aislamiento XLPE (columna 8b)
A54: Sección (mm²) | B54: Iz admisible (A)
...

Sheet Test PDF
A1: TEST: COMPARACIÓN CON EL EJEMPLO DEL PDF
A2: Válido mientras la hoja 'Cálculo' contenga los datos del ejemplo (8 viv. básicas 5.750 W, 3 elevadas 9.200 W, ascensor 5 CV, grupo presión 1 CV, alumbrado 1.500 W, locales 50 y 30 m², garaje 240 m² forzada, 30 plazas).
A5: Concepto | B5: Valor en el PDF | C5: Valor en la planilla | D5: Diferencia | E5: Tolerancia | F5: Resultado
A6: Pmedia viviendas (W) | B6: 6690.9 | C6: =Cálculo!D12 -> 6690.9091 | D6: =C6-B6 -> 0.0090909091 | E6: 0.1 | F6: =IF(ABS(D6)<=E6,"OK","REVISAR") -> OK
A7: Coeficiente de simultaneidad (11 viv.) | B7: 9.2 | C7: =Cálculo!D13 -> 9.2 | D7: =C7-B7 -> 0 | E7: 0.001 | F7: =IF(ABS(D7)<=E7,"OK","REVISAR") -> OK
A8: P1 – Potencia viviendas (W) | B8: 61556 | C8: =Cálculo!D14 -> 61556.364 | D8: =C8-B8 -> 0.36363636 | E8: 1 | F8: =IF(ABS(D8)<=E8,"OK","REVISAR") -> OK
A9: Ascensor 5 CV × 1,3 (W) | B9: 4784 | C9: =Cálculo!F19 -> 4784 | D9: =C9-B9 -> 0 | E9: 0.5 | F9: =IF(ABS(D9)<=E9,"OK","REVISAR") -> OK
A10: Grupo de presión 1 CV × 1,25 (W) | B10: 920 | C10: =Cálculo!E31 -> 920 | D10: =C10-B10 -> 0 | E10: 0.5 | F10: =IF(ABS(D10)<=E10,"OK","REVISAR") -> OK
A11: Alumbrado 1.500 W × 1,8 (W) | B11: 2700 | C11: =Cálculo!F37 -> 2700 | D11: =C11-B11 -> 0 | E11: 0.5 | F11: =IF(ABS(D11)<=E11,"OK","REVISAR") -> OK
A12: P2 – Servicios generales (W) | B12: 8404 | C12: =Cálculo!F39 -> 8404 | D12: =C12-B12 -> 0 | E12: 0.5 | F12: =IF(ABS(D12)<=E12,"OK","REVISAR") -> OK
A13: P3 – Locales (W) | B13: 8450 | C13: =Cálculo!G52 -> 8450 | D13: =C13-B13 -> 0 | E13: 0.5 | F13: =IF(ABS(D13)<=E13,"OK","REVISAR") -> OK
A14: P4 – Garaje (W) | B14: 4800 | C14: =Cálculo!F60 -> 4800 | D14: =C14-B14 -> 0 | E14: 0.5 | F14: =IF(ABS(D14)<=E14,"OK","REVISAR") -> OK
A15: TOTAL finca (W) | B15: 83210 | C15: =Resumen!B8 -> 83210.364 | D15: =C15-B15 -> 0.36363636 | E15: 1 | F15: =IF(ABS(D15)<=E15,"OK","REVISAR") -> OK
A16: IRVE opción 1 (W) | B16: 110400 | C16: =Resumen!B12 -> 110400 | D16: =C16-B16 -> 0 | E16: 0.5 | F16: =IF(ABS(D16)<=E16,"OK","REVISAR") -> OK
A17: IRVE opción 2 (W) | B17: 33120 | C17: =Resumen!B13 -> 33120 | D17: =C17-B17 -> 0 | E17: 0.5 | F17: =IF(ABS(D17)<=E17,"OK","REVISAR") -> OK
A18: IRVE opción 3 (W) | B18: 11040 | C18: =Resumen!B14 -> 11040 | D18: =C18-B18 -> 0 | E18: 0.5 | F18: =IF(ABS(D18)<=E18,"OK","REVISAR") -> OK
A19: Total opción 1 (W) | B19: 193610 | C19: =Resumen!C12 -> 193610.36 | D19: =C19-B19 -> 0.36363636 | E19: 1 | F19: =IF(ABS(D19)<=E19,"OK","REVISAR") -> OK
A20: Total opción 2 (W) | B20: 116330 | C20: =Resumen!C13 -> 116330.36 | D20: =C20-B20 -> 0.36363636 | E20: 1 | F20: =IF(ABS(D20)<=E20,"OK","REVISAR") -> OK
A21: Total opción 3 (W) | B21: 94250 | C21: =Resumen!C14 -> 94250.364 | D21: =C21-B21 -> 0.36363636 | E21: 1 | F21: =IF(ABS(D21)<=E21,"OK","REVISAR") -> OK
A22: Intensidad opción 1 total (A) | B22: 279 | C22: =Resumen!D12 -> 279.45249 | D22: =C22-B22 -> 0.45248891 | E22: 0.5 | F22: =IF(ABS(D22)<=E22,"OK","REVISAR") -> OK
A23: Intensidad IRVE opción 1 (A) | B23: 159 | C23: =Resumen!H12 -> 159.34867 | D23: =C23-B23 -> 0.3486743 | E23: 0.5 | F23: =IF(ABS(D23)<=E23,"OK","REVISAR") -> OK
A24: Intensidad finca (A) | B24: 120 | C24: =Resumen!F12 -> 120.10381 | D24: =C24-B24 -> 0.10381461 | E24: 0.5 | F24: =IF(ABS(D24)<=E24,"OK","REVISAR") -> OK
A25: Intensidad opción 2 (A) | B25: 168 | C25: =Resumen!D13 -> 167.90842 | D25: =C25-B25 -> -0.091583099 | E25: 0.5 | F25: =IF(ABS(D25)<=E25,"OK","REVISAR") -> OK
A26: Intensidad opción 3 (A) | B26: 136 | C26: =Resumen!D14 -> 136.03868 | D26: =C26-B26 -> 0.038682042 | E26: 0.5 | F26: =IF(ABS(D26)<=E26,"OK","REVISAR") -> OK
A27: Sección IRVE opción 1 (mm²) | B27: 70 | C27: =Resumen!I12 -> 70 | D27: =C27-B27 -> 0 | E27: 0 | F27: =IF(ABS(D27)<=E27,"OK","REVISAR") -> OK
A28: Sección finca opción 1 (mm²) | B28: 35 | C28: =Resumen!G12 -> 35 | D28: =C28-B28 -> 0 | E28: 0 | F28: =IF(ABS(D28)<=E28,"OK","REVISAR") -> OK
A29: Sección opción 2 (mm²) | B29: 70 | C29: =Resumen!E13 -> 70 | D29: =C29-B29 -> 0 | E29: 0 | F29: =IF(ABS(D29)<=E29,"OK","REVISAR") -> OK
A30: Sección opción 3 (mm²) | B30: 50 | C30: =Resumen!E14 -> 50 | D30: =C30-B30 -> 0 | E30: 0 | F30: =IF(ABS(D30)<=E30,"OK","REVISAR") -> OK
A32: RESULTADO GLOBAL | B32: =IF(COUNTIF(F6:F30,"REVISAR")=0,"TODO OK ("&COUNTIF(F6:F30,"OK")&" de "&ROWS(F6:F30)&")",COUNTIF(F6:F30,"REVISAR")&" valores a revisar") -> TODO OK (25 de 25)
A34: Las pequeñas diferencias (< 1 W) vienen de que el PDF redondea Pmedia a 6.690,90 W; la planilla usa el valor exacto (6.690,909… W).

Sheet Notas
A1: NOTAS Y SUPUESTOS
A3: CÓMO USAR: introduce los datos en las celdas amarillas de la hoja 'Cálculo' (viviendas, servicios generales, locales, garajes, nº de plazas IRVE). Los resultados y las secciones aparecen en 'Resumen'.
A4: FÓRMULAS (ITC-BT 10): P total = Servicios generales + Garajes + Viviendas + Locales + IRVE.
A5: Viviendas: Pmedia = Σ(nº × P IGA) / nº total; P viviendas = Pmedia × Cs (tabla de simultaneidad; n>21: 15,3 + (n−21)×0,5). Se admiten los cinco niveles de electrificación (5.750 a 14.490 W).
A6: Servicios generales: ascensores × 1,3; motores: se suma su potencia y se añade un 25 % solo al de mayor potencia; alumbrado de lámparas de descarga × 1,8. Con un único motor da lo mismo que el PDF (su esquema aplica 1,25 al grupo). Con varios motores, revisa el criterio con tu normativa/profesor.
A7: Alumbrado: puedes dar la superficie (portal, escalera: W/m² de la tabla) o una potencia instalada conocida (si hay potencia directa, tiene prioridad).
A8: Locales/oficinas: P = máx(previsión real, 100 W/m² × superficie, mínimo 3.450 W). Industrias: 125 W/m², mínimo 10.350 W.
A9: Garajes: 10 W/m² (ventilación natural) o 20 W/m² (forzada), mínimo 3.450 W.
A10: IRVE: 3.680 W por plaza. Opción 1: todas las plazas, Cs = 1 (sin SPL). Opción 2: todas las plazas, Cs = 0,3 (con SPL). Opción 3: 10 % de las plazas (redondeo hacia arriba), Cs = 1, como en los cálculos numéricos del PDF.
A11: Intensidad: trifásica 400 V y cos φ = 1 (como en el PDF: 193.610 W → 279 A). Se pueden cambiar en 'Tablas'.
A12: Sección: primera sección de cobre cuya Iz admisible ≥ I calculada. Se usa la columna 8b (3 conductores XLPE) de la tabla UNE-HD 60364-5-52, porque reproduce las secciones del ejemplo (la tabla del PDF está parcialmente tapada por una marca de agua). Modifica 'Tablas'!B55:B69 si tu instalación usa otro método. No incluye factores de corrección ni caída de tensión.
A13: No se aplica el 10 % adicional que el esquema del PDF menciona para nueva edificación (ITC-BT 52, 3.2), porque los cálculos del ejemplo tampoco lo incluyen.
A14: Herramienta de apoyo para estudio/cálculo previo: verifica siempre con el REBT vigente.
